<?xml version="1.0"?>

<robot name="arm_hardware" xmlns:xacro="http://ros.org/wiki/xacro">

  <xacro:property name="PI" value="3.14159"/>

  <xacro:macro name="mg995_servo" params="parent name llimit ulimit vlimit *origin *axis">
    <joint name="${name}_joint" type="revolute">
      <xacro:insert_block name="origin" />
      <xacro:insert_block name="axis" />
      <limit effort="1.0" velocity="${vlimit}" lower="${llimit}" upper="${ulimit}" />
      <parent link="${parent}_link"/>
      <child link="${name}_link" />
    </joint>

    <link name="${name}_link">
      <inertial>
        <mass value="0.00001" />
        <origin xyz="0 0 0" />
        <inertia ixx="1.0" ixy="0.0" ixz="0.0"
          iyy="1.0" iyz="0.0"
          izz="1.0" />
      </inertial>

      <visual>
        <origin xyz=" 0 0 0 " rpy="0 0 0" />
        <geometry>
          <mesh filename="package://r1/meshes/mg995.stl"/>
        </geometry>
         <material name="Black"/>
      </visual>

      <collision>
        <origin xyz="0.0 0.0 -0.01241" rpy="0 0 0" />
        <geometry>
          <box size="0.025 0.038 0.04762"/>
        </geometry>
      </collision>
    </link>
  </xacro:macro>


</robot>
