<?xml version="1.0"?>

<!-- XML namespaces -->
  <robot name="gizmo" xmlns:xacro="http://www.ros.org/wiki/xacro">

    <xacro:property name="PI" value="3.1415" />  
    <xacro:property name="M_PI" value="3.14159"/>
    <xacro:property name="M_SCALE" value="0.001"/>
    <xacro:property name="C_SCALE" value="0.0034"/>
    <xacro:property name="MESH_EXT" value="stl"/>
    <xacro:include filename="$(find gizmo_description)/urdf/hardware.xacro" />
    
 



<xacro:my_box name="base_footprint" lwh="0.1 0.1 0.005" xyz="0 0 0" rpy="0 0 0" mass="0.1" material="Gazebo/FlatBlack">
	        <xacro:gold />
        </xacro:my_box>

<link name="base_link" >
   <visual>
      <geometry>
        <mesh filename="package://gizmo_description/meshes/gizmo_base2.stl" scale="${M_SCALE} ${M_SCALE} ${M_SCALE}"/>
      </geometry>
         <xacro:yellow2/>
      <origin rpy="0 0 0" xyz="0 0 0"/>
    </visual>
    <collision>
        <origin xyz="-0 0 0" rpy="0 0 0" />
        <geometry>
          <box size="0.28 0.22 0.17" />-
          </geometry>
      </collision>
  </link>

<xacro:my_cylinder name="left_wheel" l="0.035" r="0.075" xyz="0 0 0" rpy="1.57 0 0" mass="0.1" material="Gazebo/Grey">
		<xacro:grey1 />
	</xacro:my_cylinder>

  <xacro:my_cylinder name="right_wheel" l="0.035" r="0.075" xyz="0 0 0" rpy="1.57 0 0" mass="0.1" material="Gazebo/Grey">
		<xacro:grey1 />
	</xacro:my_cylinder>

<link name="torso_link" >
   <visual>
      <geometry>
        <mesh filename="package://gizmo_description/meshes/gizmo_torso2.stl" scale="${M_SCALE} ${M_SCALE} ${M_SCALE}"/>
      </geometry>
         <xacro:grey1/>
      <origin rpy="0 0 0" xyz="0 0 0"/>
    </visual>
    <collision>
        <origin xyz="-0 0 0" rpy="0 0 0" />
        <geometry>
          <box size="0.28 0.28 0.17" />-
          </geometry>
      </collision>
  </link>

<xacro:ax12 name="pan_link" xyz="0 0 0" rpy=" 1.57 0 1.57">
	</xacro:ax12>

<xacro:my_box name="head_pan_link" lwh="0.15 0.1 0.005" xyz="0 0 0" rpy="0 0 0" mass="0.1" material="Gazebo/FlatBlack">
	        <xacro:blue />
        </xacro:my_box>

<xacro:ax12 name="head_tilt_link" xyz="0 0 0" rpy="0 0 3.14">
	</xacro:ax12>

<xacro:F2_bracket name="head_tilt_bracket_f2" xyz="0 0 0" rpy="0 0 0" />

<link name="neck" >
   <visual>
      <geometry>
        <mesh filename="package://gizmo_description/meshes/gizmo_neck1.stl" scale="${M_SCALE} ${M_SCALE} ${M_SCALE}"/>
      </geometry>
         <xacro:grey1/>
      <origin rpy="0 0 0" xyz="0 0 0"/>
    </visual>
    <collision>
        <origin xyz="-0 0 0" rpy="0 0 0" />
        <geometry>
          <box size="0.28 0.22 0.17" />-
          </geometry>
      </collision>
  </link>

<link name="head" >
   <visual>
      <geometry>
        <mesh filename="package://gizmo_description/meshes/head1.stl" scale="${C_SCALE} ${C_SCALE} ${C_SCALE}"/>
      </geometry>
         <xacro:grey1/>
      <origin rpy="0 0 0" xyz="0 0 0"/>
    </visual>
    <collision>
        <origin xyz="-0 0 0" rpy="0 0 0" />
        <geometry>
          <box size="0.28 0.22 0.17" />-
          </geometry>
      </collision>
  </link>
<xacro:my_cylinder name="camera_link" l="0.025" r="0.01" xyz="0 0 0" rpy="0 1.57 0" mass="0.1" material="Gazebo/Grey">		
      <xacro:grey1 />
	</xacro:my_cylinder>

<xacro:my_sphere name="right_rotate" r="0.03" xyz="0 0 0" rpy="0 0 0" mass="0.1" material="Gazebo/Grey">		
      <xacro:grey1 />
	</xacro:my_sphere>

<link name="right_lift">
      <visual>
        <origin xyz="0.075 0 0" rpy="0 0 0" />
        <geometry>
          <box size="0.15 0.01 0.03" />
        </geometry>
        <material name="grey1" />
      </visual>
  </link>

<link name="robo_servo1">
      <visual>
        <origin xyz="0.02 0 0" rpy="0 0 0" />
        <geometry>
          <box size="0.04 0.02 0.04" />
        </geometry>
        <material name="Black" />
      </visual>
  </link>

<link name="right_link">
      <visual>
        <origin xyz="0.075 0 0" rpy="0 0 0" />
        <geometry>
          <box size="0.15 0.01 0.03" />
        </geometry>
        <material name="grey1" />
      </visual>
  </link>





<!-- ##############################   joints ##################333333--> 

<joint name="base_link" type="fixed">
    	<parent link="base_footprint" />
    	<child link="base_link" />
    	<origin xyz="0.06 0 0.02" rpy="0 0 0" />
	</joint> 

 <joint name="base_link_left_wheel_joint" type="continuous">
    	<parent link="base_link" />
    	<child link="left_wheel" />
    	<origin xyz="0.03 -0.14 -0.02" rpy="0 0 0" />
	</joint>

  <joint name="base_link_right_wheel_joint" type="continuous">
    	<parent link="base_link" />
    	<child link="right_wheel" />
    	<origin xyz="0.03 0.14 -0.02" rpy="0 0 0" />
	</joint>
    
 

<joint name="torso_link" type="fixed">
    	<parent link="base_link" />
    	<child link="torso_link" />
    	<origin xyz="0.0 0 0.0" rpy="0 0 0" />
	</joint> 

<joint name="pan_link" type="fixed">
    	<parent link="torso_link" />
    	<child link="pan_link" />
    	<origin xyz="-0.06 0 0.6" rpy="0 0 0" />
	</joint> 


<!-- head_pan_joint-->	
	<joint name="head_pan_joint" type="revolute">
    	<parent link="pan_link" />
    	<child link="head_pan_link" />
    	<origin xyz="-0.04 0 0.02" rpy="0 0 3.14159" />
        <origin xyz="0 0 0.0" rpy="0 0 0" />
    	<axis xyz="0 0 1" />
    	<limit lower="-2" upper="2" effort="10" velocity="1" />
      	<dynamics damping="0.0"/>
	</joint>

<!-- head_tilt_servo-->	
	<joint name="head_tilt_link" type="fixed">
    	<parent link="head_pan_link" />
    	<child link="head_tilt_link" />
    	<origin xyz="-0.06 0 0.04" rpy="0 0 0" />
      
	</joint>

<!-- head_tilt_joint-->	
	<joint name="head_tilt_joint" type="revolute">
    	<parent link="head_tilt_link" />
    	<child link="head_tilt_bracket_f2" />
        <origin xyz="0 0 0.0" rpy="0 0 3.14" />
    	<axis xyz="0 1 0" />
    	<limit lower="2" upper="-2" effort="10" velocity="1" />
      	<dynamics damping="0.0"/>
	</joint>

<!-- neck-->	
	<joint name="neck_link" type="fixed">
    	<parent link="head_tilt_bracket_f2" />
    	<child link="neck" />
    	<origin xyz="0 0 0.02" rpy="0 0 0" />   
	</joint>

<!-- head-->	
	<joint name="head_link" type="fixed">
    	<parent link="neck" />
    	<child link="head" />
    	<origin xyz="0 0 0.05" rpy="0 0 0" />   
	</joint>

<!-- camera-->	
	<joint name="camera_link" type="fixed">
    	<parent link="head" />
    	<child link="camera_link" />
    	<origin xyz="0.065 0.055 0.005" rpy="0 0 3.14159" />   
	</joint>

<!--############################# right arm ################-->

<joint name="right_rotate_joint" type="revolute">
    	<parent link="torso_link" />
    	<child link="right_rotate" />
        <origin xyz="-0.065 0.16 0.55" rpy="0 0 0" />
    	<axis xyz="0 0 1" />
    	<limit lower="2" upper="-2" effort="10" velocity="1" />
      	<dynamics damping="0.0"/>
	</joint>

<joint name="right_lift_joint" type="revolute">
    	<parent link="right_rotate" />
    	<child link="right_lift" />
        <origin xyz="0 0.015 0" rpy="0 0 0" />
    	<axis xyz="0 1 0" />
    	<limit lower="2" upper="-2" effort="10" velocity="1" />
      	<dynamics damping="0.0"/>
	</joint>

<joint name="right_elbo_joint" type="revolute">
    	<parent link="right_lift" />
    	<child link="robo_servo1" />
        <origin xyz="0.15 0 0" rpy="0 0 0" />
    	<axis xyz="0 1 0" />
    	<limit lower="2" upper="-2" effort="10" velocity="1" />
      	<dynamics damping="0.0"/>
	</joint>

<joint name="right_forearm_link" type="fixed">
    	<parent link="robo_servo1" />
    	<child link="right_link" />
    	<origin xyz="0 0 0.0" rpy="0 0 0" />   
	</joint>



</robot>
